Workbook
Name Slicer_City1: #N/A
Name Slicer_Loan_Type1: #N/A
Name Slicer_years: #N/A

Sheet introduction

Sheet data
A1: HDFC BANK LOAN DATA 2024 TO 2026
A2: Loan_ID | B2: customer_name | C2: Age | D2: Gender | E2: City | F2: Loan_Type | G2: years | H2: months | I2: Application_Date | J2: EMI_payment_date | K2: Annual_Income | L2: monthly_income | M2: Loan_Amount | N2: month_paid | O2: total_amount_paid | P2: Interest_Rate | Q2: monthly_EMI | R2: Loan_Term_Months | S2: Credit_Score | T2: Repayment_Status | U2: good vs bad loan | V2: Default_Risk | W2: DTI | X2: Profit
A3: L0095 | B3: Meera Nair | C3: 55 | D3: Male | E3: Pune | F3: Education | G3: =YEAR(Table1[[#This Row],[Application_Date]]) -> 2024 | H3: =TEXT(Table1[[#This Row],[EMI_payment_date]],"mmmm") -> May | I3: 45383 | J3: =EDATE(Table1[[#This Row],[Application_Date]],1) -> 45413 | K3: 1728000 | L3: =Table1[[#This Row],[Annual_Income]]/12 -> 144000 | M3: 1928000 | N3: =DATEDIF(Table1[[#This Row],[EMI_payment_date]],TODAY(),"m") -> 26 | O3: =Table1[[#This Row],[month_paid]]*Table1[[#This Row],[monthly_EMI]] -> 1123200 | P3: 7.51 | Q3: =Table1[[#This Row],[monthly_income]]*30% -> 43200 | R3: =ROUNDUP(NPER(P3/100/12,-Q3,Table1[[#This Row],[Loan_Amount]]),0) -> 53 | S3: 688 | T3: Late | U3: =IF(Table1[[#This Row],[Repayment_Status]]="late","bad loan","good loan") -> bad loan | V3: =IF(Table1[[#This Row],[Repayment_Status]]="late","high","low") -> high | W3: =(Table1[[#This Row],[monthly_EMI]]/Table1[[#This Row],[monthly_income]])*100 -> 30 | X3: 31178.55
A4: L0087 | B4: Neha Yadav | C4: 26 | D4: Female | E4: Delhi | F4: Personal | G4: =YEAR(Table1[[#This Row],[Application_Date]]) -> 2024 | H4: =TEXT(Table1[[#This Row],[EMI_payment_date]],"mmmm") -> May | I4: 45384 | J4: =EDATE(Table1[[#This Row],[Application_Date]],1) -> 45414 | K4: 1632000 | L4: =Table1[[#This Row],[Annual_Income]]/12 -> 136000 | M4: 1832000 | N4: =DATEDIF(Table1[[#This Row],[EMI_payment_date]],TODAY(),"m") -> 26 | O4: =Table1[[#This Row],[month_paid]]*Table1[[#This Row],[monthly_EMI]] -> 1060800 | P4: 8.51 | Q4: =Table1[[#This Row],[monthly_income]]*30% -> 40800 | R4: =ROUNDUP(NPER(P4/100/12,-Q4,Table1[[#This Row],[Loan_Amount]]),0) -> 55 | S4: 750 | T4: Completed | U4: =IF(Table1[[#This Row],[Repayment_Status]]="late","bad loan","good loan") -> good loan | V4: =IF(Table1[[#This Row],[Repayment_Status]]="late","high","low") -> low | W4: =(Table1[[#This Row],[monthly_EMI]]/Table1[[#This Row],[monthly_income]])*100 -> 30 | X4: 23469.34
A5: L0549 | B5: Rohan Nair | C5: 29 | D5: Female | E5: Chennai | F5: Personal | G5: =YEAR(Table1[[#This Row],[Application_Date]]) -> 2024 | H5: =TEXT(Table1[[#This Row],[EMI_payment_date]],"mmmm") -> May | I5: 45385 | J5: =EDATE(Table1[[#This Row],[Application_Date]],1) -> 45415 | K5: 7176000 | L5: =Table1[[#This Row],[Annual_Income]]/12 -> 598000 | M5: 7376000 | N5: =DATEDIF(Table1[[#This Row],[EMI_payment_date]],TODAY(),"m") -> 26 | O5: =Table1[[#This Row],[month_paid]]*Table1[[#This Row],[monthly_EMI]] -> 4664400 | P5: 5.21 | Q5: =Table1[[#This Row],[monthly_income]]*30% -> 179400 | R5: =ROUNDUP(NPER(P5/100/12,-Q5,Table1[[#This Row],[Loan_Amount]]),0) -> 46 | S5: 707 | T5: Completed | U5: =IF(Table1[[#This Row],[Repayment_Status]]="late","bad loan","good loan") -> good loan | V5: =IF(Table1[[#This Row],[Repayment_Status]]="late","high","low") -> low | W5: =(Table1[[#This Row],[monthly_EMI]]/Table1[[#This Row],[monthly_income]])*100 -> 30 | X5: 10514.14
A6: L0442 | B6: Rahul Sharma | C6: 48 | D6: Female | E6: Delhi | F6: Home | G6: =YEAR(Table1[[#This Row],[Application_Date]]) -> 2024 | H6: =TEXT(Table1[[#This Row],[EMI_payment_date]],"mmmm") -> May | I6: 45386 | J6: =EDATE(Table1[[#This Row],[Application_Date]],1) -> 45416 | K6: 5892000 | L6: =Table1[[#This Row],[Annual_Income]]/12 -> 491000 | M6: 6092000 | N6: =DATEDIF(Table1[[#This Row],[EMI_payment_date]],TODAY(),"m") -> 26 | O6: =Table1[[#This Row],[month_paid]]*Table1[[#This Row],[monthly_EMI]] -> 3829800 | P6: 9.95 | Q6: =Table1[[#This Row],[monthly_income]]*30% -> 147300 | R6: =ROUNDUP(NPER(P6/100/12,-Q6,Table1[[#This Row],[Loan_Amount]]),0) -> 51 | S6: 848 | T6: Late | U6: =IF(Table1[[#This Row],[Repayment_Status]]="late","bad loan","good loan") -> bad loan | V6: =IF(Table1[[#This Row],[Repayment_Status]]="late","high","low") -> high | W6: =(Table1[[#This Row],[monthly_EMI]]/Table1[[#This Row],[monthly_income]])*100 -> 30 | X6: 26808.54
A7: L0409 | B7: Rahul Mehta | C7: 50 | D7: Male | E7: Chennai | F7: Home | G7: =YEAR(Table1[[#This Row],[Application_Date]]) -> 2024 | H7: =TEXT(Table1[[#This Row],[EMI_payment_date]],"mmmm") -> May | I7: 45387 | J7: =EDATE(Table1[[#This Row],[Application_Date]],1) -> 45417 | K7: 5496000 | L7: =Table1[[#This Row],[Annual_Income]]/12 -> 458000 | M7: 5696000 | N7: =DATEDIF(Table1[[#This Row],[EMI_payment_date]],TODAY(),"m") -> 26 | O7: =Table1[[#This Row],[month_paid]]*Table1[[#This Row],[monthly_EMI]] -> 3572400 | P7: 6.55 | Q7: =Table1[[#This Row],[monthly_income]]*30% -> 137400 | R7: =ROUNDUP(NPER(P7/100/12,-Q7,Table1[[#This Row],[Loan_Amount]]),0) -> 48 | S7: 804 | T7: Completed | U7: =IF(Table1[[#This Row],[Repayment_Status]]="late","bad loan","good loan") -> good loan | V7: =IF(Table1[[#This Row],[Repayment_Status]]="late","high","low") -> low | W7: =(Table1[[#This Row],[monthly_EMI]]/Table1[[#This Row],[monthly_income]])*100 -> 30 | X7: 25945.11
A8: L0457 | B8: Karan Mehta | C8: 36 | D8: Female | E8: Pune | F8: Personal | G8: =YEAR(Table1[[#This Row],[Application_Date]]) -> 2024 | H8: =TEXT(Table1[[#This Row],[EMI_payment_date]],"mmmm") -> May | I8: 45388 | J8: =EDATE(Table1[[#This Row],[Application_Date]],1) -> 45418 | K8: 6072000 | L8: =Table1[[#This Row],[Annual_Income]]/12 -> 506000 | M8: 6272000 | N8: =DATEDIF(Table1[[#This Row],[EMI_payment_date]],TODAY(),"m") -> 26 | O8: =Table1[[#This Row],[month_paid]]*Table1[[#This Row],[monthly_EMI]] -> 3946800 | P8: 9.26 | Q8: =Table1[[#This Row],[monthly_income]]*30% -> 151800 | R8: =ROUNDUP(NPER(P8/100/12,-Q8,Table1[[#This Row],[Loan_Amount]]),0) -> 50 | S8: 812 | T8: Completed | U8: =IF(Table1[[#This Row],[Repayment_Status]]="late","bad loan","good loan") -> good loan | V8: =IF(Table1[[#This Row],[Repayment_Status]]="late","high","low") -> low | W8: =(Table1[[#This Row],[monthly_EMI]]/Table1[[#This Row],[monthly_income]])*100 -> 30 | X8: 22853.64
A9: L0041 | B9: Kavya Yadav | C9: 23 | D9: Male | E9: Delhi | F9: Business | G9: =YEAR(Table1[[#This Row],[Application_Date]]) -> 2024 | H9: =TEXT(Table1[[#This Row],[EMI_payment_date]],"mmmm") -> May | I9: 45389 | J9: =EDATE(Table1[[#This Row],[Application_Date]],1) -> 45419 | K9: 1080000 | L9: =Table1[[#This Row],[Annual_Income]]/12 -> 90000 | M9: 1280000 | N9: =DATEDIF(Table1[[#This Row],[EMI_payment_date]],TODAY(),"m") -> 26 | O9: =Table1[[#This Row],[month_paid]]*Table1[[#This Row],[monthly_EMI]] -> 702000 | P9: 5.39 | Q9: =Table1[[#This Row],[monthly_income]]*30% -> 27000 | R9: =ROUNDUP(NPER(P9/100/12,-Q9,Table1[[#This Row],[Loan_Amount]]),0) -> 54 | S9: 831 | T9: Late | U9: =IF(Table1[[#This Row],[Repayment_Status]]="late","bad loan","good loan") -> bad loan | V9: =IF(Table1[[#This Row],[Repayment_Status]]="late","high","low") -> high | W9: =(Table1[[#This Row],[monthly_EMI]]/Table1[[#This Row],[monthly_income]])*100 -> 30 | X9: 12860.1
A10: L0545 | B10: Priya Patel | C10: 27 | D10: Male | E10: Bengaluru | F10: Home | G10: =YEAR(Table1[[#This Row],[Application_Date]]) -> 2024 | H10: =TEXT(Table1[[#This Row],[EMI_payment_date]],"mmmm") -> May | I10: 45390 | J10: =EDATE(Table1[[#This Row],[Application_Date]],1) -> 45420 | K10: 7128000 | L10: =Table1[[#This Row],[Annual_Income]]/12 -> 594000 | M10: 7328000 | N10: =DATEDIF(Table1[[#This Row],[EMI_payment_date]],TODAY(),"m") -> 26 | O10: =Table1[[#This Row],[month_paid]]*Table1[[#This Row],[monthly_EMI]] -> 4633200 | P10: 8.64 | Q10: =Table1[[#This Row],[monthly_income]]*30% -> 178200 | R10: =ROUNDUP(NPER(P10/100/12,-Q10,Table1[[#This Row],[Loan_Amount]]),0) -> 49 | S10: 732 | T10: Late | U10: =IF(Table1[[#This Row],[Repayment_Status]]="late","bad loan","good loan") -> bad loan | V10: =IF(Table1[[#This Row],[Repayment_Status]]="late","high","low") -> high | W10: =(Table1[[#This Row],[monthly_EMI]]/Table1[[#This Row],[monthly_income]])*100 -> 30 | X10: 30989.8
A11: L0346 | B11: Ananya Mehta | C11: 30 | D11: Female | E11: Hyderabad | F11: Car | G11: =YEAR(Table1[[#This Row],[Application_Date]]) -> 2024 | H11: =TEXT(Table1[[#This Row],[EMI_payment_date]],"mmmm") -> May | I11: 45391 | J11: =EDATE(Table1[[#This Row],[Application_Date]],1) -> 45421 | K11: 4740000 | L11: =Table1[[#This Row],[Annual_Income]]/12 -> 395000 | M11: 4940000 | N11: =DATEDIF(Table1[[#This Row],[EMI_payment_date]],TODAY(),"m") -> 26 | O11: =Table1[[#This Row],[month_paid]]*Table1[[#This Row],[monthly_EMI]] -> 3081000 | P11: 7.16 | Q11: =Table1[[#This Row],[monthly_income]]*30% -> 118500 | R11: =ROUNDUP(NPER(P11/100/12,-Q11,Table1[[#This Row],[Loan_Amount]]),0) -> 49 | S11: 746 | T11: Completed | U11: =IF(Table1[[#This Row],[Repayment_Status]]="late","bad loan","good loan") -> good loan | V11: =IF(Table1[[#This Row],[Repayment_Status]]="late","high","low") -> low | W11: =(Table1[[#This Row],[monthly_EMI]]/Table1[[#This Row],[monthly_income]])*100 -> 30 | X11: 26278.03
A12: L0534 | B12: Kavya Verma | C12: 37 | D12: Male | E12: Hyderabad | F12: Business | G12: =YEAR(Table1[[#This Row],[Application_Date]]) -> 2024 | H12: =TEXT(Table1[[#This Row],[EMI_payment_date]],"mmmm") -> May | I12: 45392 | J12: =EDATE(Table1[[#This Row],[Application_Date]],1) -> 45422 | K12: 6996000 | L12: =Table1[[#This Row],[Annual_Income]]/12 -> 583000 | M12: 7196000 | N12: =DATEDIF(Table1[[#This Row],[EMI_payment_date]],TODAY(),"m") -> 26 | O12: =Table1[[#This Row],[month_paid]]*Table1[[#This Row],[monthly_EMI]] -> 4547400 | P12: 9.63 | Q12: =Table1[[#This Row],[monthly_income]]*30% -> 174900 | R12: =ROUNDUP(NPER(P12/100/12,-Q12,Table1[[#This Row],[Loan_Amount]]),0) -> 51 | S12: 753 | T12: Completed | U12: =IF(Table1[[#This Row],[Repayment_Status]]="late","bad loan","good loan") -> good loan | V12: =IF(Table1[[#This Row],[Repayment_Status]]="late","high","low") -> low | W12: =(Table1[[#This Row],[monthly_EMI]]/Table1[[#This Row],[monthly_income]])*100 -> 30 | X12: 23757.02
A13: L0116 | B13: Ritika Nair | C13: 29 | D13: Female | E13: Mumbai | F13: Home | G13: =YEAR(Table1[[#This Row],[Application_Date]]) -> 2024 | H13: =TEXT(Table1[[#This Row],[EMI_payment_date]],"mmmm") -> May | I13: 45393 | J13: =EDATE(Table1[[#This Row],[Application_Date]],1) -> 45423 | K13: 1980000 | L13: =Table1[[#This Row],[Annual_Income]]/12 -> 165000 | M13: 2180000 | N13: =DATEDIF(Table1[[#This Row],[EMI_payment_date]],TODAY(),"m") -> 26 | O13: =Table1[[#This Row],[month_paid]]*Table1[[#This Row],[monthly_EMI]] -> 1287000 | P13: 7.42 | Q13: =Table1[[#This Row],[monthly_income]]*30% -> 49500 | R13: =ROUNDUP(NPER(P13/100/12,-Q13,Table1[[#This Row],[Loan_Amount]]),0) -> 52 | S13: 838 | T13: Late | U13: =IF(Table1[[#This Row],[Repayment_Status]]="late","bad loan","good loan") -> bad loan | V13: =IF(Table1[[#This Row],[Repayment_Status]]="late","high","low") -> high | W13: =(Table1[[#This Row],[monthly_EMI]]/Table1[[#This Row],[monthly_income]])*100 -> 30 | X13: 22554.62
A14: L0321 | B14: Aisha Gupta | C14: 58 | D14: Female | E14: Mumbai | F14: Personal | G14: =YEAR(Table1[[#This Row],[Application_Date]]) -> 2024 | H14: =TEXT(Table1[[#This Row],[EMI_payment_date]],"mmmm") -> May | I14: 45394 | J14: =EDATE(Table1[[#This Row],[Application_Date]],1) -> 45424 | K14: 4440000 | L14: =Table1[[#This Row],[Annual_Income]]/12 -> 370000 | M14: 4640000 | N14: =DATEDIF(Table1[[#This Row],[EMI_payment_date]],TODAY(),"m") -> 26 | O14: =Table1[[#This Row],[month_paid]]*Table1[[#This Row],[monthly_EMI]] -> 2886000 | P14: 7.88 | Q14: =Table1[[#This Row],[monthly_income]]*30% -> 111000 | R14: =ROUNDUP(NPER(P14/100/12,-Q14,Table1[[#This Row],[Loan_Amount]]),0) -> 50 | S14: 778 | T14: Completed | U14: =IF(Table1[[#This Row],[Repayment_Status]]="late","bad loan","good loan") -> good loan | V14: =IF(Table1[[#This Row],[Repayment_Status]]="late","high","low") -> low | W14: =(Table1[[#This Row],[monthly_EMI]]/Table1[[#This Row],[monthly_income]])*100 -> 30 | X14: 18855.34
... A216: L0648 | B216: Rohan Sharma | C216: 53 | D216: Male | E216: Bengaluru | F216: Business | G216: =YEAR(Table1[[#This Row],[Application_Date]]) -> 2024 | H216: =TEXT(Table1[[#This Row],[EMI_payment_date]],"mmmm") -> November | I216: 45596 | J216: =EDATE(Table1[[#This Row],[Application_Date]],1) -> 45626 | K216: 8364000 | L216: =Table1[[#This Row],[Annual_Income]]/12 -> 697000 | M216: 8564000 | N216: =DATEDIF(Table1[[#This Row],[EMI_payment_date]],TODAY(),"m") -> 20 | O216: =Table1[[#This Row],[month_paid]]*Table1[[#This Row],[monthly_EMI]] -> 4182000 | P216: 6.94 | Q216: =Table1[[#This Row],[monthly_income]]*30% -> 209100 | R216: =ROUNDUP(NPER(P216/100/12,-Q216,Table1[[#This Row],[Loan_Amount]]),0) -> 47 | S216: 661 | T216: Late | U216: =IF(Table1[[#This Row],[Repayment_Status]]="late","bad loan","good loan") -> bad loan | V216: =IF(Table1[[#This Row],[Repayment_Status]]="late","high","low") -> high | W216: =(Table1[[#This Row],[monthly_EMI]]/Table1[[#This Row],[monthly_income]])*100 -> 30 | X216: 5968.9
A217: L0568 | B217: Neha Joshi | C217: 30 | D217: Male | E217: Delhi | F217: Business | G217: =YEAR(Table1[[#This Row],[Application_Date]]) -> 2024 | H217: =TEXT(Table1[[#This Row],[EMI_payment_date]],"mmmm") -> December | I217: 45597 | J217: =EDATE(Table1[[#This Row],[Application_Date]],1) -> 45627 | K217: 7404000 | L217: =Table1[[#This Row],[Annual_Income]]/12 -> 617000 | M217: 7604000 | N217: =DATEDIF(Table1[[#This Row],[EMI_payment_date]],TODAY(),"m") -> 19 | P217: 7.9 | Q217: =Table1[[#This Row],[monthly_income]]*30% -> 185100 | R217: =ROUNDUP(NPER(P217/100/12,-Q217,Table1[[#This Row],[Loan_Amount]]),0) -> 49 | S217: 655 | T217: Late | U217: =IF(Table1[[#This Row],[Repayment_Status]]="late","bad loan","good loan") -> bad loan | V217: =IF(Table1[[#This Row],[Repayment_Status]]="late","high","low") -> high | W217: =(Table1[[#This Row],[monthly_EMI]]/Table1[[#This Row],[monthly_income]])*100 -> 30 | X217: 27841.18
A218: L0421 | B218: Arjun Singh | C218: 38 | D218: Male | E218: Chennai | F218: Education | G218: =YEAR(Table1[[#This Row],[Application_Date]]) -> 2024 | H218: =TEXT(Table1[[#This Row],[EMI_payment_date]],"mmmm") -> December | I218: 45598 | J218: =EDATE(Table1[[#This Row],[Application_Date]],1) -> 45628 | K218: 5640000 | L218: =Table1[[#This Row],[Annual_Income]]/12 -> 470000 | M218: 5840000 | N218: =DATEDIF(Table1[[#This Row],[EMI_payment_date]],TODAY(),"m") -> 19 | P218: 8.65 | Q218: =Table1[[#This Row],[monthly_income]]*30% -> 141000 | R218: =ROUNDUP(NPER(P218/100/12,-Q218,Table1[[#This Row],[Loan_Amount]]),0) -> 50 | S218: 713 | T218: Completed | U218: =IF(Table1[[#This Row],[Repayment_Status]]="late","bad loan","good loan") -> good loan | V218: =IF(Table1[[#This Row],[Repayment_Status]]="late","high","low") -> low | W218: =(Table1[[#This Row],[monthly_EMI]]/Table1[[#This Row],[monthly_income]])*100 -> 30 | X218: 31383.07
A219: L0605 | B219: Ritika Patel | C219: 50 | D219: Female | E219: Pune | F219: Home | G219: =YEAR(Table1[[#This Row],[Application_Date]]) -> 2024 | H219: =TEXT(Table1[[#This Row],[EMI_payment_date]],"mmmm") -> December | I219: 45599 | J219: =EDATE(Table1[[#This Row],[Application_Date]],1) -> 45629 | K219: 7848000 | L219: =Table1[[#This Row],[Annual_Income]]/12 -> 654000 | M219: 8048000 | N219: =DATEDIF(Table1[[#This Row],[EMI_payment_date]],TODAY(),"m") -> 19 | P219: 8.46 | Q219: =Table1[[#This Row],[monthly_income]]*30% -> 196200 | R219: =ROUNDUP(NPER(P219/100/12,-Q219,Table1[[#This Row],[Loan_Amount]]),0) -> 49 | S219: 847 | T219: Completed | U219: =IF(Table1[[#This Row],[Repayment_Status]]="late","bad loan","good loan") -> good loan | V219: =IF(Table1[[#This Row],[Repayment_Status]]="late","high","low") -> low | W219: =(Table1[[#This Row],[monthly_EMI]]/Table1[[#This Row],[monthly_income]])*100 -> 30 | X219: 23390
A220: L0002 | B220: Pooja Singh | C220: 24 | D220: Male | E220: Mumbai | F220: Car | G220: =YEAR(Table1[[#This Row],[Application_Date]]) -> 2024 | H220: =TEXT(Table1[[#This Row],[EMI_payment_date]],"mmmm") -> December | I220: 45600 | J220: =EDATE(Table1[[#This Row],[Application_Date]],1) -> 45630 | K220: 612000 | L220: =Table1[[#This Row],[Annual_Income]]/12 -> 51000 | M220: 812000 | N220: =DATEDIF(Table1[[#This Row],[EMI_payment_date]],TODAY(),"m") -> 19 | P220: 8.75 | Q220: =Table1[[#This Row],[monthly_income]]*30% -> 15300 | R220: =ROUNDUP(NPER(P220/100/12,-Q220,Table1[[#This Row],[Loan_Amount]]),0) -> 68 | S220: 755 | T220: Completed | U220: =IF(Table1[[#This Row],[Repayment_Status]]="late","bad loan","good loan") -> good loan | V220: =IF(Table1[[#This Row],[Repayment_Status]]="late","high","low") -> low | W220: =(Table1[[#This Row],[monthly_EMI]]/Table1[[#This Row],[monthly_income]])*100 -> 30 | X220: 20566.53
A221: L0032 | B221: Arjun Verma | C221: 25 | D221: Male | E221: Pune | F221: Car | G221: =YEAR(Table1[[#This Row],[Application_Date]]) -> 2024 | H221: =TEXT(Table1[[#This Row],[EMI_payment_date]],"mmmm") -> December | I221: 45601 | J221: =EDATE(Table1[[#This Row],[Application_Date]],1) -> 45631 | K221: 972000 | L221: =Table1[[#This Row],[Annual_Income]]/12 -> 81000 | M221: 1172000 | N221: =DATEDIF(Table1[[#This Row],[EMI_payment_date]],TODAY(),"m") -> 19 | O221: =20*Table1[[#This Row],[monthly_EMI]] -> 486000 | P221: 6.34 | Q221: =Table1[[#This Row],[monthly_income]]*30% -> 24300 | R221: =ROUNDUP(NPER(P221/100/12,-Q221,Table1[[#This Row],[Loan_Amount]]),0) -> 56 | S221: 654 | T221: Completed | U221: =IF(Table1[[#This Row],[Repayment_Status]]="late","bad loan","good loan") -> good loan | V221: =IF(Table1[[#This Row],[Repayment_Status]]="late","high","low") -> low | W221: =(Table1[[#This Row],[monthly_EMI]]/Table1[[#This Row],[monthly_income]])*100 -> 30 | X221: 26870.95
A222: L0677 | B222: Aarav Verma | C222: 53 | D222: Female | E222: Mumbai | F222: Home | G222: =YEAR(Table1[[#This Row],[Application_Date]]) -> 2024 | H222: =TEXT(Table1[[#This Row],[EMI_payment_date]],"mmmm") -> December | I222: 45602 | J222: =EDATE(Table1[[#This Row],[Application_Date]],1) -> 45632 | K222: 8712000 | L222: =Table1[[#This Row],[Annual_Income]]/12 -> 726000 | M222: 8912000 | N222: =DATEDIF(Table1[[#This Row],[EMI_payment_date]],TODAY(),"m") -> 19 | O222: =20*Table1[[#This Row],[monthly_EMI]] -> 4356000 | P222: 8.43 | Q222: =Table1[[#This Row],[monthly_income]]*30% -> 217800 | R222: =ROUNDUP(NPER(P222/100/12,-Q222,Table1[[#This Row],[Loan_Amount]]),0) -> 49 | S222: 846 | T222: Completed | U222: =IF(Table1[[#This Row],[Repayment_Status]]="late","bad loan","good loan") -> good loan | V222: =IF(Table1[[#This Row],[Repayment_Status]]="late","high","low") -> low | W222: =(Table1[[#This Row],[monthly_EMI]]/Table1[[#This Row],[monthly_income]])*100 -> 30 | X222: 31009.33
A223: L0314 | B223: Ananya Patel | C223: 25 | D223: Male | E223: Chennai | F223: Home | G223: =YEAR(Table1[[#This Row],[Application_Date]]) -> 2024 | H223: =TEXT(Table1[[#This Row],[EMI_payment_date]],"mmmm") -> December | I223: 45603 | J223: =EDATE(Table1[[#This Row],[Application_Date]],1) -> 45633 | K223: 4356000 | L223: =Table1[[#This Row],[Annual_Income]]/12 -> 363000 | M223: 4556000 | N223: =DATEDIF(Table1[[#This Row],[EMI_payment_date]],TODAY(),"m") -> 19 | O223: =20*Table1[[#This Row],[monthly_EMI]] -> 2178000 | P223: 5.12 | Q223: =Table1[[#This Row],[monthly_income]]*30% -> 108900 | R223: =ROUNDUP(NPER(P223/100/12,-Q223,Table1[[#This Row],[Loan_Amount]]),0) -> 47 | S223: 680 | T223: Late | U223: =IF(Table1[[#This Row],[Repayment_Status]]="late","bad loan","good loan") -> bad loan | V223: =IF(Table1[[#This Row],[Repayment_Status]]="late","high","low") -> high | W223: =(Table1[[#This Row],[monthly_EMI]]/Table1[[#This Row],[monthly_income]])*100 -> 30 | X223: 15509.56
A224: L0643 | B224: Vivaan Sharma | C224: 28 | D224: Male | E224: Delhi | F224: Business | G224: =YEAR(Table1[[#This Row],[Application_Date]]) -> 2024 | H224: =TEXT(Table1[[#This Row],[EMI_payment_date]],"mmmm") -> December | I224: 45604 | J224: =EDATE(Table1[[#This Row],[Application_Date]],1) -> 45634 | K224: 8304000 | L224: =Table1[[#This Row],[Annual_Income]]/12 -> 692000 | M224: 8504000 | N224: =DATEDIF(Table1[[#This Row],[EMI_payment_date]],TODAY(),"m") -> 19 | O224: =20*Table1[[#This Row],[monthly_EMI]] -> 4152000 | P224: 5.29 | Q224: =Table1[[#This Row],[monthly_income]]*30% -> 207600 | R224: =ROUNDUP(NPER(P224/100/12,-Q224,Table1[[#This Row],[Loan_Amount]]),0) -> 46 | S224: 667 | T224: Completed | U224: =IF(Table1[[#This Row],[Repayment_Status]]="late","bad loan","good loan") -> good loan | V224: =IF(Table1[[#This Row],[Repayment_Status]]="late","high","low") -> low | W224: =(Table1[[#This Row],[monthly_EMI]]/Table1[[#This Row],[monthly_income]])*100 -> 30 | X224: 21372.08
A225: L0684 | B225: Ishaan Sharma | C225: 28 | D225: Female | E225: Pune | F225: Car | G225: =YEAR(Table1[[#This Row],[Application_Date]]) -> 2024 | H225: =TEXT(Table1[[#This Row],[EMI_payment_date]],"mmmm") -> December | I225: 45605 | J225: =EDATE(Table1[[#This Row],[Application_Date]],1) -> 45635 | K225: 8796000 | L225: =Table1[[#This Row],[Annual_Income]]/12 -> 733000 | M225: 8996000 | N225: =DATEDIF(Table1[[#This Row],[EMI_payment_date]],TODAY(),"m") -> 19 | O225: =20*Table1[[#This Row],[monthly_EMI]] -> 4398000 | P225: 6.3 | Q225: =Table1[[#This Row],[monthly_income]]*30% -> 219900 | R225: =ROUNDUP(NPER(P225/100/12,-Q225,Table1[[#This Row],[Loan_Amount]]),0) -> 47 | S225: 650 | T225: Completed | U225: =IF(Table1[[#This Row],[Repayment_Status]]="late","bad loan","good loan") -> good loan | V225: =IF(Table1[[#This Row],[Repayment_Status]]="late","high","low") -> low | W225: =(Table1[[#This Row],[monthly_EMI]]/Table1[[#This Row],[monthly_income]])*100 -> 30 | X225: 29648.69
A226: L0427 | B226: Sanya Nair | C226: 30 | D226: Male | E226: Chennai | F226: Home | G226: =YEAR(Table1[[#This Row],[Application_Date]]) -> 2024 | H226: =TEXT(Table1[[#This Row],[EMI_payment_date]],"mmmm") -> December | I226: 45606 | J226: =EDATE(Table1[[#This Row],[Application_Date]],1) -> 45636 | K226: 5712000 | L226: =Table1[[#This Row],[Annual_Income]]/12 -> 476000 | M226: 5912000 | N226: =DATEDIF(Table1[[#This Row],[EMI_payment_date]],TODAY(),"m") -> 19 | O226: =20*Table1[[#This Row],[monthly_EMI]] -> 2856000 | P226: 8.66 | Q226: =Table1[[#This Row],[monthly_income]]*30% -> 142800 | R226: =ROUNDUP(NPER(P226/100/12,-Q226,Table1[[#This Row],[Loan_Amount]]),0) -> 50 | S226: 696 | T226: Late | U226: =IF(Table1[[#This Row],[Repayment_Status]]="late","bad loan","good loan") -> bad loan | V226: =IF(Table1[[#This Row],[Repayment_Status]]="late","high","low") -> high | W226: =(Table1[[#This Row],[monthly_EMI]]/Table1[[#This Row],[monthly_income]])*100 -> 30 | X226: 24105.06
A227: L0323 | B227: Ishaan Singh | C227: 41 | D227: Female | E227: Delhi | F227: Education | G227: =YEAR(Table1[[#This Row],[Application_Date]]) -> 2024 | H227: =TEXT(Table1[[#This Row],[EMI_payment_date]],"mmmm") -> December | I227: 45607 | J227: =EDATE(Table1[[#This Row],[Application_Date]],1) -> 45637 | K227: 4464000 | L227: =Table1[[#This Row],[Annual_Income]]/12 -> 372000 | M227: 4664000 | N227: =DATEDIF(Table1[[#This Row],[EMI_payment_date]],TODAY(),"m") -> 19 | O227: =20*Table1[[#This Row],[monthly_EMI]] -> 2232000 | P227: 6.22 | Q227: =Table1[[#This Row],[monthly_income]]*30% -> 111600 | R227: =ROUNDUP(NPER(P227/100/12,-Q227,Table1[[#This Row],[Loan_Amount]]),0) -> 48 | S227: 795 | T227: Completed | U227: =IF(Table1[[#This Row],[Repayment_Status]]="late","bad loan","good loan") -> good loan | V227: =IF(Table1[[#This Row],[Repayment_Status]]="late","high","low") -> low | W227: =(Table1[[#This Row],[monthly_EMI]]/Table1[[#This Row],[monthly_income]])*100 -> 30 | X227: 14076.54
A228: L0369 | B228: Kavya Nair | C228: 40 | D228: Female | E228: Hyderabad | F228: Business | G228: =YEAR(Table1[[#This Row],[Application_Date]]) -> 2024 | H228: =TEXT(Table1[[#This Row],[EMI_payment_date]],"mmmm") -> December | I228: 45608 | J228: =EDATE(Table1[[#This Row],[Application_Date]],1) -> 45638 | K228: 5016000 | L228: =Table1[[#This Row],[Annual_Income]]/12 -> 418000 | M228: 5216000 | N228: =DATEDIF(Table1[[#This Row],[EMI_payment_date]],TODAY(),"m") -> 19 | O228: =20*Table1[[#This Row],[monthly_EMI]] -> 2508000 | P228: 6.75 | Q228: =Table1[[#This Row],[monthly_income]]*30% -> 125400 | R228: =ROUNDUP(NPER(P228/100/12,-Q228,Table1[[#This Row],[Loan_Amount]]),0) -> 48 | S228: 717 | T228: Late | U228: =IF(Table1[[#This Row],[Repayment_Status]]="late","bad loan","good loan") -> bad loan | V228: =IF(Table1[[#This Row],[Repayment_Status]]="late","high","low") -> high | W228: =(Table1[[#This Row],[monthly_EMI]]/Table1[[#This Row],[monthly_income]])*100 -> 30 | X228: 11695.08
A229: L0675 | B229: Sanya Gupta | C229: 53 | D229: Female | E229: Chennai | F229: Business | G229: =YEAR(Table1[[#This Row],[Application_Date]]) -> 2024 | H229: =TEXT(Table1[[#This Row],[EMI_payment_date]],"mmmm") -> December | I229: 45609 | J229: =EDATE(Table1[[#This Row],[Application_Date]],1) -> 45639 | K229: 8688000 | L229: =Table1[[#This Row],[Annual_Income]]/12 -> 724000 | M229: 8888000 | N229: =DATEDIF(Table1[[#This Row],[EMI_payment_date]],TODAY(),"m") -> 19 | O229: =20*Table1[[#This Row],[monthly_EMI]] -> 4344000 | P229: 8.66 | Q229: =Table1[[#This Row],[monthly_income]]*30% -> 217200 | R229: =ROUNDUP(NPER(P229/100/12,-Q229,Table1[[#This Row],[Loan_Amount]]),0) -> 49 | S229: 827 | T229: Completed | U229: =IF(Table1[[#This Row],[Repayment_Status]]="late","bad loan","good loan") -> good loan | V229: =IF(Table1[[#This Row],[Repayment_Status]]="late","high","low") -> low | W229: =(Table1[[#This Row],[monthly_EMI]]/Table1[[#This Row],[monthly_income]])*100 -> 30 | X229: 6854.06
A230: L0692 | B230: Ritika Singh | C230: 45 | D230: Female | E230: Mumbai | F230: Business | G230: =YEAR(Table1[[#This Row],[Application_Date]]) -> 2024 | H230: =TEXT(Table1[[#This Row],[EMI_payment_date]],"mmmm") -> December | I230: 45610 | J230: =EDATE(Table1[[#This Row],[Application_Date]],1) -> 45640 | K230: 8892000 | L230: =Table1[[#This Row],[Annual_Income]]/12 -> 741000 | M230: 9092000 | N230: =DATEDIF(Table1[[#This Row],[EMI_payment_date]],TODAY(),"m") -> 19 | O230: =20*Table1[[#This Row],[monthly_EMI]] -> 4446000 | P230: 7.14 | Q230: =Table1[[#This Row],[monthly_income]]*30% -> 222300 | R230: =ROUNDUP(NPER(P230/100/12,-Q230,Table1[[#This Row],[Loan_Amount]]),0) -> 48 | S230: 795 | T230: Completed | U230: =IF(Table1[[#This Row],[Repayment_Status]]="late","bad loan","good loan") -> good loan | V230: =IF(Table1[[#This Row],[Repayment_Status]]="late","high","low") -> low | W230: =(Table1[[#This Row],[monthly_EMI]]/Table1[[#This Row],[monthly_income]])*100 -> 30 | X230: 21982.52
A231: L0289 | B231: Aarav Kumar | C231: 51 | D231: Female | E231: Chennai | F231: Home | G231: =YEAR(Table1[[#This Row],[Application_Date]]) -> 2024 | H231: =TEXT(Table1[[#This Row],[EMI_payment_date]],"mmmm") -> December | I231: 45611 | J231: =EDATE(Table1[[#This Row],[Application_Date]],1) -> 45641 | K231: 4056000 | L231: =Table1[[#This Row],[Annual_Income]]/12 -> 338000 | M231: 4256000 | N231: =DATEDIF(Table1[[#This Row],[EMI_payment_date]],TODAY(),"m") -> 19 | O231: =20*Table1[[#This Row],[monthly_EMI]] -> 2028000 | P231: 7.36 | Q231: =Table1[[#This Row],[monthly_income]]*30% -> 101400 | R231: =ROUNDUP(NPER(P231/100/12,-Q231,Table1[[#This Row],[Loan_Amount]]),0) -> 49 | S231: 742 | T231: Completed | U231: =IF(Table1[[#This Row],[Repayment_Status]]="late","bad loan","good loan") -> good loan | V231: =IF(Table1[[#This Row],[Repayment_Status]]="late","high","low") -> low | W231: =(Table1[[#This Row],[monthly_EMI]]/Table1[[#This Row],[monthly_income]])*100 -> 30 | X231: 33182.71
A232: L0094 | B232: Aryan Joshi | C232: 56 | D232: Male | E232: Bengaluru | F232: Business | G232: =YEAR(Table1[[#This Row],[Application_Date]]) -> 2024 | H232: =TEXT(Table1[[#This Row],[EMI_payment_date]],"mmmm") -> December | I232: 45612 | J232: =EDATE(Table1[[#This Row],[Application_Date]],1) -> 45642 | K232: 1716000 | L232: =Table1[[#This Row],[Annual_Income]]/12 -> 143000 | M232: 1916000 | N232: =DATEDIF(Table1[[#This Row],[EMI_payment_date]],TODAY(),"m") -> 19 | O232: =20*Table1[[#This Row],[monthly_EMI]] -> 858000 | P232: 6.2 | Q232: =Table1[[#This Row],[monthly_income]]*30% -> 42900 | R232: =ROUNDUP(NPER(P232/100/12,-Q232,Table1[[#This Row],[Loan_Amount]]),0) -> 51 | S232: 752 | T232: Completed | U232: =IF(Table1[[#This Row],[Repayment_Status]]="late","bad loan","good loan") -> good loan | V232: =IF(Table1[[#This Row],[Repayment_Status]]="late","high","low") -> low | W232: =(Table1[[#This Row],[monthly_EMI]]/Table1[[#This Row],[monthly_income]])*100 -> 30 | X232: 22244.94
... A246: L0447 | B246: Aditya Sharma | C246: 50 | D246: Female | E246: Delhi | F246: Personal | G246: =YEAR(Table1[[#This Row],[Application_Date]]) -> 2024 | H246: =TEXT(Table1[[#This Row],[EMI_payment_date]],"mmmm") -> December | I246: 45626 | J246: =EDATE(Table1[[#This Row],[Application_Date]],1) -> 45656 | K246: 5952000 | L246: =Table1[[#This Row],[Annual_Income]]/12 -> 496000 | M246: 6152000 | N246: =DATEDIF(Table1[[#This Row],[EMI_payment_date]],TODAY(),"m") -> 19 | O246: =20*Table1[[#This Row],[monthly_EMI]] -> 2976000 | P246: 6.61 | Q246: =Table1[[#This Row],[monthly_income]]*30% -> 148800 | R246: =ROUNDUP(NPER(P246/100/12,-Q246,Table1[[#This Row],[Loan_Amount]]),0) -> 48 | S246: 714 | T246: Completed | U246: =IF(Table1[[#This Row],[Repayment_Status]]="late","bad loan","good loan") -> good loan | V246: =IF(Table1[[#This Row],[Repayment_Status]]="late","high","low") -> low | W246: =(Table1[[#This Row],[monthly_EMI]]/Table1[[#This Row],[monthly_income]])*100 -> 30 | X246: 16622.17
A247: L0353 | B247: Pooja Joshi | C247: 37 | D247: Female | E247: Delhi | F247: Home | G247: =YEAR(Table1[[#This Row],[Application_Date]]) -> 2024 | H247: =TEXT(Table1[[#This Row],[EMI_payment_date]],"mmmm") -> January | I247: 45627 | J247: =EDATE(Table1[[#This Row],[Application_Date]],1) -> 45658 | K247: 4824000 | L247: =Table1[[#This Row],[Annual_Income]]/12 -> 402000 | M247: 5024000 | N247: =DATEDIF(Table1[[#This Row],[EMI_payment_date]],TODAY(),"m") -> 18 | O247: =19*Table1[[#This Row],[monthly_EMI]] -> 2291400 | P247: 5.07 | Q247: =Table1[[#This Row],[monthly_income]]*30% -> 120600 | R247: =ROUNDUP(NPER(P247/100/12,-Q247,Table1[[#This Row],[Loan_Amount]]),0) -> 46 | S247: 785 | T247: Completed | U247: =IF(Table1[[#This Row],[Repayment_Status]]="late","bad loan","good loan") -> good loan | V247: =IF(Table1[[#This Row],[Repayment_Status]]="late","high","low") -> low | W247: =(Table1[[#This Row],[monthly_EMI]]/Table1[[#This Row],[monthly_income]])*100 -> 30 | X247: 5837.2
A248: L0291 | B248: Sanya Yadav | C248: 56 | D248: Male | E248: Hyderabad | F248: Education | G248: =YEAR(Table1[[#This Row],[Application_Date]]) -> 2024 | H248: =TEXT(Table1[[#This Row],[EMI_payment_date]],"mmmm") -> January | I248: 45628 | J248: =EDATE(Table1[[#This Row],[Application_Date]],1) -> 45659 | K248: 4080000 | L248: =Table1[[#This Row],[Annual_Income]]/12 -> 340000 | M248: 4280000 | N248: =DATEDIF(Table1[[#This Row],[EMI_payment_date]],TODAY(),"m") -> 18 | O248: =19*Table1[[#This Row],[monthly_EMI]] -> 1938000 | P248: 7.55 | Q248: =Table1[[#This Row],[monthly_income]]*30% -> 102000 | R248: =ROUNDUP(NPER(P248/100/12,-Q248,Table1[[#This Row],[Loan_Amount]]),0) -> 49 | S248: 740 | T248: Completed | U248: =IF(Table1[[#This Row],[Repayment_Status]]="late","bad loan","good loan") -> good loan | V248: =IF(Table1[[#This Row],[Repayment_Status]]="late","high","low") -> low | W248: =(Table1[[#This Row],[monthly_EMI]]/Table1[[#This Row],[monthly_income]])*100 -> 30 | X248: 30749.25
A249: L0394 | B249: Meera Yadav | C249: 33 | D249: Female | E249: Delhi | F249: Home | G249: =YEAR(Table1[[#This Row],[Application_Date]]) -> 2024 | H249: =TEXT(Table1[[#This Row],[EMI_payment_date]],"mmmm") -> January | I249: 45629 | J249: =EDATE(Table1[[#This Row],[Application_Date]],1) -> 45660 | K249: 5316000 | L249: =Table1[[#This Row],[Annual_Income]]/12 -> 443000 | M249: 5516000 | N249: =DATEDIF(Table1[[#This Row],[EMI_payment_date]],TODAY(),"m") -> 18 | O249: =19*Table1[[#This Row],[monthly_EMI]] -> 2525100 | P249: 5.58 | Q249: =Table1[[#This Row],[monthly_income]]*30% -> 132900 | R249: =ROUNDUP(NPER(P249/100/12,-Q249,Table1[[#This Row],[Loan_Amount]]),0) -> 47 | S249: 781 | T249: Completed | U249: =IF(Table1[[#This Row],[Repayment_Status]]="late","bad loan","good loan") -> good loan | V249: =IF(Table1[[#This Row],[Repayment_Status]]="late","high","low") -> low | W249: =(Table1[[#This Row],[monthly_EMI]]/Table1[[#This Row],[monthly_income]])*100 -> 30 | X249: 12118.87
A250: L0564 | B250: Pooja Verma | C250: 26 | D250: Female | E250: Delhi | F250: Education | G250: =YEAR(Table1[[#This Row],[Application_Date]]) -> 2024 | H250: =TEXT(Table1[[#This Row],[EMI_payment_date]],"mmmm") -> January | I250: 45630 | J250: =EDATE(Table1[[#This Row],[Application_Date]],1) -> 45661 | K250: 7356000 | L250: =Table1[[#This Row],[Annual_Income]]/12 -> 613000 | M250: 7556000 | N250: =DATEDIF(Table1[[#This Row],[EMI_payment_date]],TODAY(),"m") -> 18 | O250: =19*Table1[[#This Row],[monthly_EMI]] -> 3494100 | P250: 9.68 | Q250: =Table1[[#This Row],[monthly_income]]*30% -> 183900 | R250: =ROUNDUP(NPER(P250/100/12,-Q250,Table1[[#This Row],[Loan_Amount]]),0) -> 51 | S250: 719 | T250: Completed | U250: =IF(Table1[[#This Row],[Repayment_Status]]="late","bad loan","good loan") -> good loan | V250: =IF(Table1[[#This Row],[Repayment_Status]]="late","high","low") -> low | W250: =(Table1[[#This Row],[monthly_EMI]]/Table1[[#This Row],[monthly_income]])*100 -> 30 | X250: 22220.17
A251: L0231 | B251: Kavya Gupta | C251: 41 | D251: Female | E251: Bengaluru | F251: Personal | G251: =YEAR(Table1[[#This Row],[Application_Date]]) -> 2024 | H251: =TEXT(Table1[[#This Row],[EMI_payment_date]],"mmmm") -> January | I251: 45631 | J251: =EDATE(Table1[[#This Row],[Application_Date]],1) -> 45662 | K251: 3360000 | L251: =Table1[[#This Row],[Annual_Income]]/12 -> 280000 | M251: 3560000 | N251: =DATEDIF(Table1[[#This Row],[EMI_payment_date]],TODAY(),"m") -> 18 | O251: =19*Table1[[#This Row],[monthly_EMI]] -> 1596000 | P251: 6.15 | Q251: =Table1[[#This Row],[monthly_income]]*30% -> 84000 | R251: =ROUNDUP(NPER(P251/100/12,-Q251,Table1[[#This Row],[Loan_Amount]]),0) -> 48 | S251: 608 | T251: Completed | U251: =IF(Table1[[#This Row],[Repayment_Status]]="late","bad loan","good loan") -> good loan | V251: =IF(Table1[[#This Row],[Repayment_Status]]="late","high","low") -> low | W251: =(Table1[[#This Row],[monthly_EMI]]/Table1[[#This Row],[monthly_income]])*100 -> 30 | X251: 16377.07
A252: L0187 | B252: Priya Yadav | C252: 24 | D252: Female | E252: Mumbai | F252: Business | G252: =YEAR(Table1[[#This Row],[Application_Date]]) -> 2024 | H252: =TEXT(Table1[[#This Row],[EMI_payment_date]],"mmmm") -> January | I252: 45632 | J252: =EDATE(Table1[[#This Row],[Application_Date]],1) -> 45663 | K252: 2832000 | L252: =Table1[[#This Row],[Annual_Income]]/12 -> 236000 | M252: 3032000 | N252: =DATEDIF(Table1[[#This Row],[EMI_payment_date]],TODAY(),"m") -> 18 | O252: =19*Table1[[#This Row],[monthly_EMI]] -> 1345200 | P252: 6.9 | Q252: =Table1[[#This Row],[monthly_income]]*30% -> 70800 | R252: =ROUNDUP(NPER(P252/100/12,-Q252,Table1[[#This Row],[Loan_Amount]]),0) -> 50 | S252: 686 | T252: Completed | U252: =IF(Table1[[#This Row],[Repayment_Status]]="late","bad loan","good loan") -> good loan | V252: =IF(Table1[[#This Row],[Repayment_Status]]="late","high","low") -> low | W252: =(Table1[[#This Row],[monthly_EMI]]/Table1[[#This Row],[monthly_income]])*100 -> 30 | X252: 19390.31
A253: L0508 | B253: Ananya Verma | C253: 23 | D253: Male | E253: Mumbai | F253: Business | G253: =YEAR(Table1[[#This Row],[Application_Date]]) -> 2024 | H253: =TEXT(Table1[[#This Row],[EMI_payment_date]],"mmmm") -> January | I253: 45633 | J253: =EDATE(Table1[[#This Row],[Application_Date]],1) -> 45664 | K253: 6684000 | L253: =Table1[[#This Row],[Annual_Income]]/12 -> 557000 | M253: 6884000 | N253: =DATEDIF(Table1[[#This Row],[EMI_payment_date]],TODAY(),"m") -> 18 | O253: =19*Table1[[#This Row],[monthly_EMI]] -> 3174900 | P253: 8.57 | Q253: =Table1[[#This Row],[monthly_income]]*30% -> 167100 | R253: =ROUNDUP(NPER(P253/100/12,-Q253,Table1[[#This Row],[Loan_Amount]]),0) -> 49 | S253: 743 | T253: Completed | U253: =IF(Table1[[#This Row],[Repayment_Status]]="late","bad loan","good loan") -> good loan | V253: =IF(Table1[[#This Row],[Repayment_Status]]="late","high","low") -> low | W253: =(Table1[[#This Row],[monthly_EMI]]/Table1[[#This Row],[monthly_income]])*100 -> 30 | X253: 20954.28
A254: L0123 | B254: Ritika Gupta | C254: 28 | D254: Female | E254: Bengaluru | F254: Personal | G254: =YEAR(Table1[[#This Row],[Application_Date]]) -> 2024 | H254: =TEXT(Table1[[#This Row],[EMI_payment_date]],"mmmm") -> January | I254: 45634 | J254: =EDATE(Table1[[#This Row],[Application_Date]],1) -> 45665 | K254: 2064000 | L254: =Table1[[#This Row],[Annual_Income]]/12 -> 172000 | M254: 2264000 | N254: =DATEDIF(Table1[[#This Row],[EMI_payment_date]],TODAY(),"m") -> 18 | O254: =19*Table1[[#This Row],[monthly_EMI]] -> 980400 | P254: 5.85 | Q254: =Table1[[#This Row],[monthly_income]]*30% -> 51600 | R254: =ROUNDUP(NPER(P254/100/12,-Q254,Table1[[#This Row],[Loan_Amount]]),0) -> 50 | S254: 722 | T254: Completed | U254: =IF(Table1[[#This Row],[Repayment_Status]]="late","bad loan","good loan") -> good loan | V254: =IF(Table1[[#This Row],[Repayment_Status]]="late","high","low") -> low | W254: =(Table1[[#This Row],[monthly_EMI]]/Table1[[#This Row],[monthly_income]])*100 -> 30 | X254: 15758.99
...

Sheet pivot table
A2: total metrics | D2: gender wise customer and loan amount | H2: Repayment Status wise customers | K2: city wise analysis | N2: Average Income by City
A3: metrics | D3: Row Labels | E3: Sum of Loan_Amount | F3: Count of Loan_ID | H3: Row Labels | I3: Count of Loan_ID | K3: Row Labels | L3: Count of Loan_ID | N3: Row Labels | O3: Average of Annual_Income
A4: Count of Loan_ID | B4: 699 | D4: Female | E4: 1709408000 | F4: 337 | H4: Completed | I4: 457 | K4: Bengaluru | L4: 119 | N4: Bengaluru | O4: 4881075.6
A5: Sum of Loan_Amount | B5: 3494112000 | D5: Male | E5: 1784704000 | F5: 362 | H5: Late | I5: 242 | K5: Chennai | L5: 107 | N5: Chennai | O5: 4964972
A6: Average of Interest_Rate | B6: 7.5090844 | K6: Delhi | L6: 136 | N6: Delhi | O6: 4823735.3
A7: Average of total_amount_paid | B7: 1930221.6 | D7: City Wise Good vs Bad Loan analysis | K7: Hyderabad | L7: 110 | N7: Hyderabad | O7: 4779709.1
A8: Average of DTI | B8: 30 | D8: Count of Loan_ID | E8: Column Labels | H8: Default Risk Distribution | K8: Mumbai | L8: 116 | N8: Mumbai | O8: 4543344.8
A9: Sum of Profit | B9: 14829045 | D9: Row Labels | E9: bad loan | F9: good loan | H9: Row Labels | I9: Count of Loan_ID | K9: Pune | L9: 111 | N9: Pune | O9: 4805297.3
D10: Bengaluru | E10: 38 | F10: 81 | H10: high | I10: 242
A11: loan tpye wise analysis | D11: Chennai | E11: 37 | F11: 70 | H11: low | I11: 457 | K11: Average Interest Rate by Loan Type | N11: loan taken by city
A12: Row Labels | B12: Sum of Loan_Amount | D12: Delhi | E12: 58 | F12: 78 | K12: Row Labels | L12: Average of Interest_Rate | N12: Row Labels | O12: Sum of Loan_Amount
A13: Business | B13: 675944000 | D13: Hyderabad | E13: 38 | F13: 72 | K13: Business | L13: 7.6013971 | N13: Bengaluru | O13: 604648000
A14: Car | B14: 661352000 | D14: Mumbai | E14: 34 | F14: 82 | H14: Total Profit by Loan Type | K14: Car | L14: 7.5224194 | N14: Chennai | O14: 552652000
A15: Education | B15: 739476000 | D15: Pune | E15: 37 | F15: 74 | H15: Row Labels | I15: Sum of Profit | K15: Education | L15: 7.5765359 | N15: Delhi | O15: 683228000
A16: Home | B16: 706604000 | H16: Business | I16: 2862769.3 | K16: Home | L16: 7.4301408 | N16: Hyderabad | O16: 547768000
A17: Personal | B17: 710736000 | D17: Total Amount Paid by Loan Type | H17: Car | I17: 2799302.7 | K17: Personal | L17: 7.4165972 | N17: Mumbai | O17: 550228000
D18: Row Labels | E18: Sum of total_amount_paid | H18: Education | I18: 3151641.1 | N18: Pune | O18: 555588000
A19: City Wise Profit | D19: Business | E19: 268450500 | H19: Home | I19: 3135051.7
A20: Row Labels | B20: Sum of Profit | D20: Car | E20: 255999300 | H20: Personal | I20: 2880280 | K20: Total EMI Collected
A21: Bengaluru | B21: 2477866.4 | D21: Education | E21: 258431100 | K21: Row Labels | L21: Sum of monthly_EMI
A22: Chennai | B22: 2123362.9 | D22: Home | E22: 280035600 | K22: Business | L22: 16218600
A23: Delhi | B23: 3050533.5 | D23: Personal | E23: 278587500 | K23: Car | L23: 15913800
A24: Hyderabad | B24: 2207168.3 | K24: Education | L24: 17721900
A25: Mumbai | B25: 2573551 | K25: Home | L25: 16955100
A26: Pune | B26: 2396562.7 | K26: Personal | L26: 17048400

Sheet deshboard
A8: total loan ID | G8: total loan amount | M8: average loan interest rate | S8: total amount recevied | X8: profit
A10: =GETPIVOTDATA("Count of Loan_ID",'pivot table'!$A$3) -> 699 | G10: =GETPIVOTDATA("Sum of Loan_Amount",'pivot table'!$A$3) -> 3494112000 | M10: =GETPIVOTDATA("Average of Interest_Rate",'pivot table'!$A$3) -> 7.5090844 | S10: =GETPIVOTDATA("Average of total_amount_paid",'pivot table'!$A$3) -> 1930221.6 | X10: =GETPIVOTDATA("Sum of Profit",'pivot table'!$A$3) -> 14829045

Sheet insights

Sheet formula used 
A1: formula used | B1: explanation
A2: =_xlfn.FORMULATEXT(data!J3) -> =EDATE([@[Application_Date]],1) | B2: Calculates the first EMI payment date by adding one month to the application date.
A3: =_xlfn.FORMULATEXT(Table1[[#This Row],[years]]) -> =YEAR([@[Application_Date]]) | B3: Calculates and extracts the year from the Application Date for year-wise analysis and reporting.
A4: =_xlfn.FORMULATEXT(Table1[[#This Row],[months]]) -> =TEXT([@[EMI_payment_date]],"mmmm") | B4: Extracts the full month name from the EMI payment date.
A5: =_xlfn.FORMULATEXT(data!L3) -> =[@[Annual_Income]]/12 | B5: Calculates the customer's monthly income from the annual income.
A6: =_xlfn.FORMULATEXT(data!Q3) -> =[@[monthly_income]]*30% | B6: Calculates 30% of the customer's monthly income to estimate the affordable EMI amount.
A7: =_xlfn.FORMULATEXT(data!O3) -> =[@[month_paid]]*[@[monthly_EMI]] | B7: Calculates the total amount paid by multiplying the number of EMIs paid by the monthly EMI amount.
A8: =_xlfn.FORMULATEXT(data!N3) -> =DATEDIF([@[EMI_payment_date]],TODAY(),"m") | B8: Calculates the total number of months elapsed since the EMI payment started.
A9: =_xlfn.FORMULATEXT(data!R3) -> =ROUNDUP(NPER(P3/100/12,-Q3,[@[Loan_Amount]]),0) | B9: Calculates the total loan repayment period (in months) and rounds it up to the nearest whole month.
A10: =_xlfn.FORMULATEXT(data!U3) -> =IF([@[Repayment_Status]]="late","bad loan","good loan") | B10: Classifies the loan as Good Loan or Bad Loan based on the repayment status.
A11: =_xlfn.FORMULATEXT(data!V3) -> =IF([@[Repayment_Status]]="late","high","low") | B11: Determines the default risk level as High or Low based on the repayment status.
A12: =_xlfn.FORMULATEXT(data!W3) -> =([@[monthly_EMI]]/[@[monthly_income]])*100 | B12: Calculates the Debt-to-Income (DTI) ratio by expressing the monthly EMI as a percentage of the monthly income.
